cn11.hpc.itu.dk
W1129 12:19:15.527000 140239647712256 torch/distributed/run.py:779] 
W1129 12:19:15.527000 140239647712256 torch/distributed/run.py:779] *****************************************
W1129 12:19:15.527000 140239647712256 torch/distributed/run.py:779] Setting OMP_NUM_THREADS environment variable for each process to be 1 in default, to avoid your system being overloaded, please further tune the variable for optimal performance in your application as needed. 
W1129 12:19:15.527000 140239647712256 torch/distributed/run.py:779] *****************************************
2024-11-29 12:19:24.669	cn11.hpc.itu.dk:0	train:380	INFO	CLI environment prepared
OLMoConfigurationError: Key 'pretrained_model_name_or_path' not in 'ModelConfig'
    full_key: model.pretrained_model_name_or_path
    reference_type=ModelConfig
    object_type=ModelConfig
OLMoConfigurationError: Key 'pretrained_model_name_or_path' not in 'ModelConfig'
    full_key: model.pretrained_model_name_or_path
    reference_type=ModelConfig
    object_type=ModelConfig
[rank0]:[W1129 12:19:25.327893618 ProcessGroupNCCL.cpp:1168] Warning: WARNING: process group has NOT been destroyed before we destruct ProcessGroupNCCL. On normal program exit, the application should call destroy_process_group to ensure that any pending NCCL operations have finished in this process. In rare cases this process can exit before this point and block the progress of another member of the process group. This constraint has always been present,  but this warning has only been added since PyTorch 2.4 (function operator())
W1129 12:19:26.151000 140239647712256 torch/distributed/elastic/multiprocessing/api.py:858] Sending process 4068896 closing signal SIGTERM
E1129 12:19:26.215000 140239647712256 torch/distributed/elastic/multiprocessing/api.py:833] failed (exitcode: 1) local_rank: 0 (pid: 4068895) of binary: /home/ccor/.conda/envs/captum_test/bin/python
Traceback (most recent call last):
  File "/home/ccor/.conda/envs/captum_test/bin/torchrun", line 8, in <module>
    sys.exit(main())
             ^^^^^^
  File "/home/ccor/.conda/envs/captum_test/lib/python3.11/site-packages/torch/distributed/elastic/multiprocessing/errors/__init__.py", line 348, in wrapper
    return f(*args, **kwargs)
           ^^^^^^^^^^^^^^^^^^
  File "/home/ccor/.conda/envs/captum_test/lib/python3.11/site-packages/torch/distributed/run.py", line 901, in main
    run(args)
  File "/home/ccor/.conda/envs/captum_test/lib/python3.11/site-packages/torch/distributed/run.py", line 892, in run
    elastic_launch(
  File "/home/ccor/.conda/envs/captum_test/lib/python3.11/site-packages/torch/distributed/launcher/api.py", line 133, in __call__
    return launch_agent(self._config, self._entrypoint, list(args))
           ^^^^^^^^^^^^^^^^^^^^^^^^^^^^^^^^^^^^^^^^^^^^^^^^^^^^^^^^
  File "/home/ccor/.conda/envs/captum_test/lib/python3.11/site-packages/torch/distributed/launcher/api.py", line 264, in launch_agent
    raise ChildFailedError(
torch.distributed.elastic.multiprocessing.errors.ChildFailedError: 
============================================================
train.py FAILED
------------------------------------------------------------
Failures:
  <NO_OTHER_FAILURES>
------------------------------------------------------------
Root Cause (first observed failure):
[0]:
  time      : 2024-11-29_12:19:26
  host      : cn11.hpc.itu.dk
  rank      : 0 (local_rank: 0)
  exitcode  : 1 (pid: 4068895)
  error_file: <N/A>
  traceback : To enable traceback see: https://pytorch.org/docs/stable/elastic/errors.html
============================================================
