cn13.hpc.itu.dk
Monitoring_GPUs_on_HPC
ResearchProject
captum_test.job
captum_test.png
captum_test.py
hpc_saliency_test.py
logs
neuralcoref
qaskills
qatest.job
requirements.txt
saliency_test.csv
saliency_test2.tsv
simple.job
stupid.py
test.job
LICENSE
README.md
captum_test.py
classes.py
finetune.job
helpers.py
journal.md
logs
sanna_test.ipynb
train.py
train_comp.json
train_labels.npy
train_token_ids.npy
training.yaml
val_comp.json
val_labels.npy
val_token_ids.npy
W1128 10:01:27.989000 139772056637760 torch/distributed/run.py:779] 
W1128 10:01:27.989000 139772056637760 torch/distributed/run.py:779] *****************************************
W1128 10:01:27.989000 139772056637760 torch/distributed/run.py:779] Setting OMP_NUM_THREADS environment variable for each process to be 1 in default, to avoid your system being overloaded, please further tune the variable for optimal performance in your application as needed. 
W1128 10:01:27.989000 139772056637760 torch/distributed/run.py:779] *****************************************
2024-11-28 10:01:35.458	cn13.hpc.itu.dk:0	train:380	INFO	CLI environment prepared
2024-11-28 10:01:35.476	cn13.hpc.itu.dk:1	olmo.util:165	CRITICAL	Uncaught FileNotFoundError: [Errno 2] No such file or directory: '/home/ccor/ResearchProject/--config'
Traceback (most recent call last):
  File "/home/ccor/ResearchProject/train.py", line 389, in <module>
    cfg = TrainConfig.load(yaml_path, [clean_opt(s) for s in args_list])
          ^^^^^^^^^^^^^^^^^^^^^^^^^^^^^^^^^^^^^^^^^^^^^^^^^^^^^^^^^^^^^^
  File "/home/ccor/.conda/envs/captum_test/lib/python3.11/site-packages/olmo/config.py", line 138, in load
    raw = om.load(str(path))
          ^^^^^^^^^^^^^^^^^^
  File "/home/ccor/.conda/envs/captum_test/lib/python3.11/site-packages/omegaconf/omegaconf.py", line 189, in load
    with io.open(os.path.abspath(file_), "r", encoding="utf-8") as f:
         ^^^^^^^^^^^^^^^^^^^^^^^^^^^^^^^^^^^^^^^^^^^^^^^^^^^^^^
FileNotFoundError: [Errno 2] No such file or directory: '/home/ccor/ResearchProject/--config'
2024-11-28 10:01:35.489	cn13.hpc.itu.dk:0	olmo.util:165	CRITICAL	Uncaught FileNotFoundError: [Errno 2] No such file or directory: '/home/ccor/ResearchProject/--config'
Traceback (most recent call last):
  File "/home/ccor/ResearchProject/train.py", line 389, in <module>
    cfg = TrainConfig.load(yaml_path, [clean_opt(s) for s in args_list])
          ^^^^^^^^^^^^^^^^^^^^^^^^^^^^^^^^^^^^^^^^^^^^^^^^^^^^^^^^^^^^^^
  File "/home/ccor/.conda/envs/captum_test/lib/python3.11/site-packages/olmo/config.py", line 138, in load
    raw = om.load(str(path))
          ^^^^^^^^^^^^^^^^^^
  File "/home/ccor/.conda/envs/captum_test/lib/python3.11/site-packages/omegaconf/omegaconf.py", line 189, in load
    with io.open(os.path.abspath(file_), "r", encoding="utf-8") as f:
         ^^^^^^^^^^^^^^^^^^^^^^^^^^^^^^^^^^^^^^^^^^^^^^^^^^^^^^
FileNotFoundError: [Errno 2] No such file or directory: '/home/ccor/ResearchProject/--config'
[rank0]:[W1128 10:01:35.509068893 ProcessGroupNCCL.cpp:1168] Warning: WARNING: process group has NOT been destroyed before we destruct ProcessGroupNCCL. On normal program exit, the application should call destroy_process_group to ensure that any pending NCCL operations have finished in this process. In rare cases this process can exit before this point and block the progress of another member of the process group. This constraint has always been present,  but this warning has only been added since PyTorch 2.4 (function operator())
W1128 10:01:37.207000 139772056637760 torch/distributed/elastic/multiprocessing/api.py:858] Sending process 672077 closing signal SIGTERM
E1128 10:01:37.371000 139772056637760 torch/distributed/elastic/multiprocessing/api.py:833] failed (exitcode: 1) local_rank: 1 (pid: 672078) of binary: /home/ccor/.conda/envs/captum_test/bin/python
Traceback (most recent call last):
  File "/home/ccor/.conda/envs/captum_test/bin/torchrun", line 8, in <module>
    sys.exit(main())
             ^^^^^^
  File "/home/ccor/.conda/envs/captum_test/lib/python3.11/site-packages/torch/distributed/elastic/multiprocessing/errors/__init__.py", line 348, in wrapper
    return f(*args, **kwargs)
           ^^^^^^^^^^^^^^^^^^
  File "/home/ccor/.conda/envs/captum_test/lib/python3.11/site-packages/torch/distributed/run.py", line 901, in main
    run(args)
  File "/home/ccor/.conda/envs/captum_test/lib/python3.11/site-packages/torch/distributed/run.py", line 892, in run
    elastic_launch(
  File "/home/ccor/.conda/envs/captum_test/lib/python3.11/site-packages/torch/distributed/launcher/api.py", line 133, in __call__
    return launch_agent(self._config, self._entrypoint, list(args))
           ^^^^^^^^^^^^^^^^^^^^^^^^^^^^^^^^^^^^^^^^^^^^^^^^^^^^^^^^
  File "/home/ccor/.conda/envs/captum_test/lib/python3.11/site-packages/torch/distributed/launcher/api.py", line 264, in launch_agent
    raise ChildFailedError(
torch.distributed.elastic.multiprocessing.errors.ChildFailedError: 
============================================================
train.py FAILED
------------------------------------------------------------
Failures:
  <NO_OTHER_FAILURES>
------------------------------------------------------------
Root Cause (first observed failure):
[0]:
  time      : 2024-11-28_10:01:37
  host      : cn13.hpc.itu.dk
  rank      : 1 (local_rank: 1)
  exitcode  : 1 (pid: 672078)
  error_file: <N/A>
  traceback : To enable traceback see: https://pytorch.org/docs/stable/elastic/errors.html
============================================================
